<?xml version="1.0" encoding="utf-8"?>
<!-- =================================================================================== -->
<!-- |    This document was autogenerated by xacro from /home/pohzhiee/catkin_ws/src/lobot_description/robots/arm_standalone.urdf.xacro | -->
<!-- |    EDITING THIS FILE BY HAND IS NOT RECOMMENDED                                 | -->
<!-- =================================================================================== -->
<robot name="lobot" xmlns:xacro="http://ros.org/wiki/xacro">
  <material name="Blue">
    <color rgba="0.0 0.0 0.8 1.0"/>
  </material>
  <material name="Green">
    <color rgba="0.0 0.8 0.0 1.0"/>
  </material>
  <material name="Grey">
    <color rgba="0.7 0.7 0.7 1.0"/>
  </material>
  <material name="LightGrey">
    <color rgba="0.9 0.9 0.9 1.0"/>
  </material>
  <material name="DarkGrey">
    <color rgba="0.2 0.2 0.2 1.0"/>
  </material>
  <material name="Red">
    <color rgba="0.8 0.0 0.0 1.0"/>
  </material>
  <material name="White">
    <color rgba="1.0 1.0 1.0 1.0"/>
  </material>

<link name="robot_base">
<visual>
    <geometry>
        <box size="0.03 0.03 0.01"/>
    </geometry>    
    <material name="black"/>
</visual>    
</link>
  <joint name="world_joint" type="fixed">
    <parent link="robot_base"/>
    <child link="arm_1_link"/>
    <origin rpy="0 0 0" xyz="0 0 0.03"/>
  </joint>
  <link name="arm_1_link">
    <inertial>
      <mass value="0.06"/>
      <origin rpy="0 0 0" xyz="0 0 0"/>
      <inertia ixx="0.0" ixy="0.0" ixz="0.0" iyy="0.0" iyz="0.0" izz="0.0"/>
    </inertial>
    <visual>
      <origin rpy="0 0 0" xyz="0 0 0"/>
      <geometry>
        <box size="0.02 0.04 0.04"/>
      </geometry>
      <material name="LightGrey"/>
    </visual>
    <collision>
      <origin rpy="0 0 0" xyz="0 0 0"/>
      <geometry>
        <box size="0.02 0.04 0.04"/>
      </geometry>
    </collision>
  </link>
  <joint name="arm_1_joint" type="revolute">
    <origin rpy="0 0 0" xyz="0 0.01 0.0"/>
    <axis xyz="0 0 1"/>
    <parent link="arm_1_link"/>
    <child link="arm_bracket_1"/>
    <limit effort="3.5" lower="-2.356" upper="2.356" velocity="10"/>
  </joint>
  <link name="arm_bracket_1">
    <inertial>
      <mass value="0.00658"/>
      <origin rpy="0 0 0" xyz="0 0 0.03693"/>
      <inertia ixx="0.00097149" ixy="0.0" ixz="0.0" iyy="0.00390446" iyz="0.0" izz="0.00346115"/>
    </inertial>
    <visual>
      <origin rpy="0 0 0" xyz="0 0 0.029"/>
      <geometry>
        <box size="0.052 0.025 0.002"/>
      </geometry>
      <material name="Green"/>
    </visual>
    <collision>
      <origin rpy="0 0 0" xyz="0 0 0.029"/>
      <geometry>
        <box size="0.052 0.025 0.002"/>
      </geometry>
    </collision>
  </link>
  <joint name="arm_2_joint" type="revolute">
    <origin rpy="0 0 0" xyz="0 0 0.052"/>
    <axis xyz="1 0 0"/>
    <parent link="arm_bracket_1"/>
    <child link="arm_2_link"/>
    <limit effort="3" lower="-1.570796" upper="1.570796" velocity="20"/>
  </joint>
  <!-- arm_2_link = motor2 -->
  <link name="arm_2_link">
    <inertial>
      <mass value="0.0618"/>
      <origin rpy="0 0 0" xyz="0.0005 -0.01505 0"/>
      <inertia ixx="0.00703304" ixy="-0.00250174" ixz="0.0" iyy="0.00793603" iyz="0.0" izz="0.01230371"/>
    </inertial>
    <visual>
      <origin rpy="0 0 0" xyz="0 -0.01 0"/>
      <geometry>
        <box size="0.04 0.04 0.02"/>
      </geometry>
      <material name="LightGrey"/>
    </visual>
    <collision>
      <origin rpy="0 0 0" xyz="0 -0.01 0"/>
      <geometry>
        <box size="0.04 0.04 0.02"/>
      </geometry>
    </collision>
  </link>
  <!-- arm_bracket_2 = Asm_WeldedBracket -->
  <link name="arm_bracket_2">
    <inertial>
      <mass value="0.01175"/>
      <origin rpy="0 0 0" xyz="0 -0.0029 0"/>
      <inertia ixx="0.00229954" ixy="0.0" ixz="0.0" iyy="0.00519619" iyz="0.0" izz="0.00648306"/>
    </inertial>
    <visual>
      <origin rpy="0 0 0" xyz="0 0 0"/>
      <geometry>
        <box size="0.055 0.002 0.025"/>
      </geometry>
      <material name="Green"/>
    </visual>
    <collision>
      <origin rpy="0 0 0" xyz="0 0 0"/>
      <geometry>
        <box size="0.055 0.002 0.025"/>
      </geometry>
    </collision>
  </link>
  <joint name="arm_bracket_2_joint" type="fixed">
    <parent link="arm_2_link"/>
    <child link="arm_bracket_2"/>
    <origin rpy="0 0 0" xyz="0 -0.03653 0"/>
  </joint>
  <joint name="arm_3_joint" type="revolute">
    <origin rpy="0 0 0" xyz="0 -0.06 0"/>
    <axis xyz="1 0 0"/>
    <parent link="arm_2_link"/>
    <child link="arm_3_link"/>
    <limit effort="3" lower="-1.570796" upper="1.570796" velocity="10"/>
  </joint>
  <!-- arm_3_link = motor3 -->
  <link name="arm_3_link">
    <inertial>
      <mass value="0.0618"/>
      <origin rpy="0 0 0" xyz="0.0005 -0.01505 0"/>
      <inertia ixx="0.00703304" ixy="-0.00250174" ixz="0.0" iyy="0.00793603" iyz="0.0" izz="0.01230371"/>
    </inertial>
    <visual>
      <origin rpy="0 0 0" xyz="0 -0.01 0"/>
      <geometry>
        <box size="0.04 0.04 0.02"/>
      </geometry>
      <material name="LightGrey"/>
    </visual>
    <collision>
      <origin rpy="0 0 0" xyz="0 -0.01 0"/>
      <geometry>
        <box size="0.04 0.04 0.02"/>
      </geometry>
    </collision>
  </link>
  <!-- The entire grippper mass property is put on the first link -->
  <joint name="grip_joint_1" type="fixed">
    <parent link="arm_3_link"/>
    <child link="grip_link_1"/>
    <origin rpy="0 0 0" xyz="0 -0.0475 0.01"/>
  </joint>
  <link name="grip_link_1">
    <inertial>
      <mass value="0.01023"/>
      <origin rpy="0 0 0" xyz="0 -0.05355 0"/>
      <inertia ixx="0.00443574" ixy="0.0" ixz="0.0" iyy="0.00287052" iyz="0.00000684" izz="0.00651523"/>
    </inertial>
    <visual>
      <origin rpy="0 0 0" xyz="0 0 0"/>
      <geometry>
        <box size="0.04 0.055 0.001"/>
      </geometry>
      <material name="White"/>
    </visual>
    <collision>
      <origin rpy="0 0 0" xyz="0 0 0"/>
      <geometry>
        <box size="0.04 0.055 0.001"/>
      </geometry>
    </collision>
  </link>
  <joint name="grip_joint_2" type="fixed">
    <parent link="arm_3_link"/>
    <child link="grip_link_2"/>
    <origin rpy="0 0 0" xyz="0 -0.0815 0.0033"/>
  </joint>
  <link name="grip_link_2">
    <inertial>
      <mass value="0.005"/>
      <origin rpy="0.785398 0 0" xyz="0 0 0"/>
      <inertia ixx="0.0" ixy="0.0" ixz="0.0" iyy="0.0" iyz="0.0" izz="0.0"/>
    </inertial>
    <visual>
      <origin rpy="0.785398 0 0" xyz="0 0 0"/>
      <geometry>
        <box size="0.04 0.017 0.001"/>
      </geometry>
      <material name="White"/>
    </visual>
    <collision>
      <origin rpy="0.785398 0 0" xyz="0 0 0"/>
      <geometry>
        <box size="0.04 0.017 0.001"/>
      </geometry>
    </collision>
  </link>
  <joint name="grip_joint_3" type="fixed">
    <parent link="arm_3_link"/>
    <child link="grip_link_3"/>
    <origin rpy="0 0 0" xyz="0 -0.088 -0.0067"/>
  </joint>
  <link name="grip_link_3">
    <inertial>
      <mass value="0.005"/>
      <origin rpy="0 0 0" xyz="0 0 0"/>
      <inertia ixx="0.0" ixy="0.0" ixz="0.0" iyy="0.0" iyz="0.0" izz="0.0"/>
    </inertial>
    <visual>
      <origin rpy="0 0 0" xyz="0 0 0"/>
      <geometry>
        <box size="0.04 0.001 0.007"/>
      </geometry>
      <material name="White"/>
    </visual>
    <collision>
      <origin rpy="0 0 0" xyz="0 0 0"/>
      <geometry>
        <box size="0.04 0.001 0.007"/>
      </geometry>
    </collision>
  </link>
  <joint name="grip_joint_4" type="fixed">
    <parent link="grip_link_3"/>
    <child link="grip_end_point"/>
    <origin rpy="0 0 0" xyz="0 -0.0005 -0.0035"/>
  </joint>
  <link name="grip_end_point">
    <inertial>
      <mass value="0.0000001"/>
      <origin rpy="0 0 0" xyz="0 0 0"/>
      <inertia ixx="0.0" ixy="0.0" ixz="0.0" iyy="0.0" iyz="0.0" izz="0.0"/>
    </inertial>
    <visual>
      <origin rpy="0 0 0" xyz="0 0 0"/>
      <geometry>
        <sphere radius="0.001"/>
      </geometry>
      <material name="Red"/>
    </visual>
  </link>
</robot>

